package pointers_errors

import (
	"testing"
)

func TestWallet(t *testing.T) {

	assertBalance := func(t *testing.T, got Bitcoin, want Bitcoin) {
		if got != want {
			t.Errorf("got %s want %s", got, want)
		}
	}

	t.Run("Deposit", func(t *testing.T) {
		wallet := Wallet{}
		wallet.Deposit(Bitcoin(10))
		got := wallet.Balance()

		assertBalance(t, got, Bitcoin(10))
	})

	t.Run("Withdraw", func(t *testing.T) {
		wallet := Wallet{balance: Bitcoin(20)}
		err := wallet.Withdraw(Bitcoin(10))
		got := wallet.Balance()

		assertBalance(t, got, Bitcoin(10))
		assertNoError(t, err)
	})

	assertError := func(t *testing.T, got error, want error) {
		t.Helper()

		if got == nil {
			t.Fatal("didn't get an error but wanted one")
		}

		if got != want {
			t.Errorf("got %q, want %q", got, want)
		}
	}

	t.Run("Withdraw insufficient funds", func(t *testing.T) {
		startingBalance := Bitcoin(20)
		wallet := Wallet{startingBalance}
		err := wallet.Withdraw(Bitcoin(100))

		assertError(t, err, ErrInsufficientFunds)
	})
}

func assertNoError(t *testing.T, got error) {
	t.Helper()
	if got != nil {
		t.Fatal("got an error but didn't want one")
	}
}
